Workbook

Sheet 00_Portada
A1: CUEVA - Modelo financiero definitivo
A2: Motor 2030, inversion acumulada 4,2M y plan 26/27 de 300K en pestañas separadas.
A5: Convencion | B5: Valor | D5: Output clave | E5: Valor | F5: Notas
A6: Documento | B6: Modelo financiero definitivo | D6: Ingresos 2030 | E6: ='02_Detalle_Ingresos'!E42 | F6: Desde 02_Detalle_Ingresos
A7: Fecha | B7: 2026-07-16 | D7: EBITDA 2030 | E7: ='06_Cuenta_Resultados'!E22 | F7: Desde 06_Cuenta_Resultados
A8: Moneda | B8: EUR M salvo indicacion | D8: Resultado neto 2030 | E8: ='06_Cuenta_Resultados'!E29 | F8: Despues de amortizacion, financiero e impuestos
A9: Eje temporal | B9: 2026/27 + 2028-2030 | D9: Margen EBITDA 2030 | E9: ='06_Cuenta_Resultados'!E23 | F9: EBITDA / ingresos
A10: Escenario | B10: Management / Scale revisado | D10: m2 objetivo acumulado | E10: ='01_Supuestos'!B5 | F10: Curva base original ajustada por tramo 300k
A11: Modelo | B11: Plan 2030 separado de inversion acumulada y plan 300K | D11: Estado modelo | E11: ='08_Control'!E16 | F11: Desde 08_Control
A13: Lectura | B13: El tramo 2026/27 agrupa lanzamiento y validacion comercial; 2028-2030 escalan red, producto y recurrencia.
A15: Contenido del modelo definitivo
A16: 1 | B16: Hojas, etiquetas y navegacion en castellano.
A17: 2 | B17: Cuenta de resultados completa: ingresos, margen bruto, OPEX, EBITDA, amortizacion, resultado financiero, impuestos y resultado neto.
A18: 3 | B18: OPEX operativo desarrollado por driver: plataforma, IA/API, ciberseguridad, kits de campo, QA, soporte, GTM, legal, finanzas y reserva.
A19: 4 | B19: Detalle de personal por departamento, perfil, sueldo medio y FTE.
A20: 5 | B20: Detalle de ingresos por digitalizacion, fees de red, POI, DPP, recurrencia, datos, marketplace, iPath, Moolde, internacional y capa financiera.
A21: 6 | B21: Controles de coherencia con estado OK/REVISAR/FALLO.
A22: 7 | B22: Hoja de paquetes de producto para conectar producto, drivers economicos y entregables.
A23: 8 | B23: Pestañas separadas para inversion acumulada 4,2M y plan 26/27 de 300K.
A25: Principio | B25: Todo lo azul es input editable; todo lo verde es formula o enlace de modelo.

Sheet 01_Supuestos
A1: 01 Supuestos
A2: Inputs editables en azul. La curva base mantiene el crecimiento original; solo se redistribuye el sobrante del tramo 2026/27.
A4: Control de m2 y escala
A5: Total m2 objetivo plan | B5: =SUM(B7:E7) | F5: Total derivado de la curva base original. Si se modifica B7:E7 recalcula el total.
A6: m2 tramo 2026/27 | B6: 300000 | F6: Input solicitado: 300k m2 en el tramo unificado 2026/27.
A7: m2 base original antes de ajuste | B7: 586000 | C7: 1065000 | D7: 1920000 | E7: 2940000 | F7: Curva original: 2026+2027, 2028, 2029 y 2030. Mantiene crecimiento no lineal.
A8: m2 emitidos | B8: =$B$6 | C8: =C7+MAX(0,$B$7-$B$6)/3 | D8: =D7+MAX(0,$B$7-$B$6)/3 | E8: =E7+MAX(0,$B$7-$B$6)/3 | F8: B = 300k; C/D/E = curva original + sobrante 2026/27 redistribuido.
A9: Stock vivo | B9: =B8 | C9: =B9+C8 | D9: =C9+D8 | E9: =D9+E8 | F9: Acumulado de m2 emitidos.
A10: Partners activos | B10: 5 | C10: 11 | D10: 17 | E10: 23 | F10: Escala comercial por periodo.
A11: Sobrante 2026/27 redistribuido | B11: =MAX(0,$B$7-$B$6) | C11: =B11/3 | D11: =B11/3 | E11: =B11/3 | F11: B = sobrante total; C/D/E = reparto igualitario sobre 2028-2030.
A12: Unit economics, adopcion y verticales
A13: Concepto | B13: 2026/27 | C13: 2028 | D13: 2029 | E13: 2030 | F13: Notas / driver
A14: Fee de Red Fabricante EUR/m2 | B14: 2.5 | C14: 2.5 | D14: 2.5 | E14: 2.5 | F14: Servicio de red fabricante por m2 fabricado verificado.
A15: Fee de Red Montaje EUR/m2 | B15: 2.5 | C15: 2.5 | D15: 2.5 | E15: 2.5 | F15: Servicio de red montaje por m2 instalado/verificado.
A16: Cobertura fee montaje | B16: 0.85 | C16: 0.9 | D16: 0.93 | E16: 0.95 | F16: Cobertura progresiva del trigger de montaje.
A17: Precio Designer EUR/m2 | B17: 3 | C17: 3.2 | D17: 3.3 | E17: 3.5 | F17: Precio por m2 emitido.
A18: Adopcion Designer | B18: 0.72 | C18: 0.78 | D18: 0.82 | E18: 0.86 | F18: Adopcion sobre m2 emitidos.
A19: Precio Manager EUR/m2 | B19: 2.6 | C19: 2.7 | D19: 2.8 | E19: 3 | F19: Precio por m2 emitido.
A20: Adopcion Manager | B20: 0.82 | C20: 0.88 | D20: 0.92 | E20: 0.95 | F20: Adopcion sobre m2 emitidos.
A21: Precio Asset Activation EUR/m2 | B21: 5 | C21: 6.5 | D21: 7.25 | E21: 8 | F21: Activacion de activo por m2 emitido.
A22: Completion Asset Activation | B22: 0.88 | C22: 0.95 | D22: 0.92 | E22: 1 | F22: Porcentaje de cierre/activacion.
A23: Precio POI base EUR/m2 | B23: 3.4 | C23: 4.1 | D23: 4.8 | E23: 5.5 | F23: POI base por m2.
A24: Uplift POI | B24: 0.2 | C24: 0.25 | D24: 0.25 | E24: 0.25 | F24: Complejidad/servicios adicionales.
A25: POI completion | B25: 0.78 | C25: 0.9 | D25: 0.92 | E25: 0.95 | F25: Porcentaje de eventos POI completados.
... A41: Financial Layer revenue EUR M | B41: 0.3 | C41: 1.2 | D41: 3 | E41: 9 | F41: Capa financiera / datos / servicios.
A44: Margenes, cash, amortizacion y financiacion
A45: Concepto | B45: 2026/27 | C45: 2028 | D45: 2029 | E45: 2030 | F45: Notas / driver
A46: Margen Asset OS | B46: 0.75 | C46: 0.77 | D46: 0.79 | E46: 0.82 | F46: Aplicado al resto de Asset OS excluyendo digitalizacion y fees especificos.
A47: Margen iPath | B47: 0.4 | C47: 0.42 | D47: 0.44 | E47: 0.48 | F47: Margen de contribucion vertical iPath.
A48: Margen Marketplace | B48: 0.8 | C48: 0.82 | D48: 0.84 | E48: 0.86 | F48: Margen de contribucion Marketplace.
A49: Margen Internacional | B49: 0.65 | C49: 0.68 | D49: 0.7 | E49: 0.75 | F49: Margen contribucion internacional.
A50: Margen Financial Layer | B50: 0.68 | C50: 0.72 | D50: 0.75 | E50: 0.85 | F50: Margen servicios financieros/datos.
A51: GM digitalizacion fabricante | B51: 0.58 | C51: 0.6 | D51: 0.62 | E51: 0.65 | F51: Margen por paquete de digitalizacion fabricante.
A52: GM digitalizacion montaje | B52: 0.62 | C52: 0.65 | D52: 0.67 | E52: 0.7 | F52: Margen por paquete de digitalizacion montaje.
A53: GM fee fabricante | B53: 0.86 | C53: 0.87 | D53: 0.88 | E53: 0.9 | F53: Margen sobre fee fabricante.
A54: GM fee montaje | B54: 0.84 | C54: 0.86 | D54: 0.87 | E54: 0.88 | F54: Margen sobre fee montaje.
A55: Margen Moolde | B55: 1 | C55: 1 | D55: 1 | E55: 1 | F55: Moolde se modela como contribucion neta.
A56: WC % crecimiento | B56: 0.15 | C56: 0.16 | D56: 0.17 | E56: 0.18 | F56: Capital circulante incremental sobre crecimiento de ingresos.
A57: Capex EUR M | B57: 2 | C57: 2.5 | D57: 3 | E57: 4 | F57: Capex de plataforma, producto y despliegue.
... A61: Gasto financiero EUR M | B61: 0.21 | C61: 0.105 | D61: 0 | E61: 0 | F61: Coste financiero estimado asociado a la financiacion externa.

Sheet 02_Detalle_Ingresos
A1: 02 Detalle de ingresos
A2: Ingresos por concepto, driver y formula. EUR M salvo counts, m2 y tarifas.
A4: Digitalizacion de partners
A5: Concepto | B5: 2026/27 | C5: 2028 | D5: 2029 | E5: 2030 | F5: Tarifa / driver | G5: Notas | H5: Fuente
A6: Nuevos fabricantes - Small | B6: 1 | C6: 0 | D6: 1 | E6: 0 | F6: 50.000 EUR | G6: Paquete cerrado hasta 5.000 m2 | H6: Economics de partners
A7: Nuevos fabricantes - Growth | B7: 1 | C7: 1 | D7: 0 | E7: 0 | F7: 120.000 EUR | G7: Paquete cerrado growth | H7: Economics de partners
A8: Nuevos fabricantes - Scale | B8: 0 | C8: 1 | D8: 1 | E8: 2 | F8: 250.000 EUR | G8: Paquete cerrado scale | H8: Economics de partners
A9: Nuevos fabricantes - Enterprise | B9: 0 | C9: 0 | D9: 1 | E9: 1 | F9: 400.000 EUR | G9: Desde 400k | H9: Economics de partners
A10: Revenue digitalizacion fabricante | B10: =B6*50000/1000000+B7*120000/1000000+B8*250000/1000000+B9*400000/1000000 | C10: =C6*50000/1000000+C7*120000/1000000+C8*250000/1000000+C9*400000/1000000 | D10: =D6*50000/1000000+D7*120000/1000000+D8*250000/1000000+D9*400000/1000000 | E10: =E6*50000/1000000+E7*120000/1000000+E8*250000/1000000+E9*400000/1000000 | F10: SUMPRODUCT tiers | G10: EUR M | H10: Formula
A11: Nuevos montadores - Starter | B11: 0 | C11: 2 | D11: 1 | E11: 1 | F11: 35.000 EUR | G11: Hasta 2 cuadrillas | H11: Economics de partners
A12: Nuevos montadores - Scale | B12: 1 | C12: 1 | D12: 1 | E12: 1 | F12: 75.000 EUR | G12: 3 a 6 cuadrillas | H12: Economics de partners
A13: Nuevos montadores - Enterprise | B13: 0 | C13: 1 | D13: 1 | E13: 1 | F13: 12.000 EUR/cuadrilla, min. 75k | G13: Mas de 6 cuadrillas | H13: Economics de partners
A14: Cuadrillas medias Enterprise | B14: 6 | C14: 8 | D14: 10 | E14: 12 | F14: Input | G14: Driver para enterprise | H14: Economics de partners
A15: Revenue digitalizacion montaje | B15: =B11*35000/1000000+B12*75000/1000000+B13*MAX(75000,B14*12000)/1000000 | C15: =C11*35000/1000000+C12*75000/1000000+C13*MAX(75000,C14*12000)/1000000 | D15: =D11*35000/1000000+D12*75000/1000000+D13*MAX(75000,D14*12000)/1000000 | E15: =E11*35000/1000000+E12*75000/1000000+E13*MAX(75000,E14*12000)/1000000 | F15: SUM tiers | G15: EUR M | H15: Formula
A18: Usage-Based Construction Asset OS
A19: Concepto | B19: 2026/27 | C19: 2028 | D19: 2029 | E19: 2030 | F19: Driver | G19: Formula | H19: Notas
A20: Digitalizacion fabricante | B20: ='02_Detalle_Ingresos'!B10 | C20: ='02_Detalle_Ingresos'!C10 | D20: ='02_Detalle_Ingresos'!D10 | E20: ='02_Detalle_Ingresos'!E10 | F20: Partner tiers | G20: Counts x tarifa / 1M | H20: Paquete de activacion de fabricante
A21: Digitalizacion montaje | B21: ='02_Detalle_Ingresos'!B15 | C21: ='02_Detalle_Ingresos'!C15 | D21: ='02_Detalle_Ingresos'!D15 | E21: ='02_Detalle_Ingresos'!E15 | F21: Crew tiers | G21: Counts x tarifa / 1M | H21: Paquete de activacion de montadores
A22: Fee de Red Fabricante | B22: ='01_Supuestos'!B8*'01_Supuestos'!B14/1000000 | C22: ='01_Supuestos'!C8*'01_Supuestos'!C14/1000000 | D22: ='01_Supuestos'!D8*'01_Supuestos'!D14/1000000 | E22: ='01_Supuestos'!E8*'01_Supuestos'!E14/1000000 | F22: m2 emitidos | G22: m2 x fee fabricante | H22: Trigger: m2 fabricados verificados
A23: Fee de Red Montaje | B23: ='01_Supuestos'!B8*'01_Supuestos'!B15*'01_Supuestos'!B16/1000000 | C23: ='01_Supuestos'!C8*'01_Supuestos'!C15*'01_Supuestos'!C16/1000000 | D23: ='01_Supuestos'!D8*'01_Supuestos'!D15*'01_Supuestos'!D16/1000000 | E23: ='01_Supuestos'!E8*'01_Supuestos'!E15*'01_Supuestos'!E16/1000000 | F23: m2 emitidos x cobertura | G23: m2 x fee x cobertura | H23: Trigger: m2 instalados/verificados
A24: Designer | B24: ='01_Supuestos'!B8*'01_Supuestos'!B17*'01_Supuestos'!B18/1000000 | C24: ='01_Supuestos'!C8*'01_Supuestos'!C17*'01_Supuestos'!C18/1000000 | D24: ='01_Supuestos'!D8*'01_Supuestos'!D17*'01_Supuestos'!D18/1000000 | E24: ='01_Supuestos'!E8*'01_Supuestos'!E17*'01_Supuestos'!E18/1000000 | F24: m2 emitidos | G24: m2 x precio x adopcion | H24: Diseno/generativo/API
A25: Manager | B25: ='01_Supuestos'!B8*'01_Supuestos'!B19*'01_Supuestos'!B20/1000000 | C25: ='01_Supuestos'!C8*'01_Supuestos'!C19*'01_Supuestos'!C20/1000000 | D25: ='01_Supuestos'!D8*'01_Supuestos'!D19*'01_Supuestos'!D20/1000000 | E25: ='01_Supuestos'!E8*'01_Supuestos'!E19*'01_Supuestos'!E20/1000000 | F25: m2 emitidos | G25: m2 x precio x adopcion | H25: Manager y project room
A26: Asset Activation | B26: ='01_Supuestos'!B8*'01_Supuestos'!B21*'01_Supuestos'!B22/1000000 | C26: ='01_Supuestos'!C8*'01_Supuestos'!C21*'01_Supuestos'!C22/1000000 | D26: ='01_Supuestos'!D8*'01_Supuestos'!D21*'01_Supuestos'!D22/1000000 | E26: ='01_Supuestos'!E8*'01_Supuestos'!E21*'01_Supuestos'!E22/1000000 | F26: m2 emitidos | G26: m2 x precio x completion | H26: Activacion inicial del activo
A27: POI Evidence Pack | B27: ='01_Supuestos'!B8*'01_Supuestos'!B23*(1+'01_Supuestos'!B24)*'01_Supuestos'!B25/1000000 | C27: ='01_Supuestos'!C8*'01_Supuestos'!C23*(1+'01_Supuestos'!C24)*'01_Supuestos'!C25/1000000 | D27: ='01_Supuestos'!D8*'01_Supuestos'!D23*(1+'01_Supuestos'!D24)*'01_Supuestos'!D25/1000000 | E27: ='01_Supuestos'!E8*'01_Supuestos'!E23*(1+'01_Supuestos'!E24)*'01_Supuestos'!E25/1000000 | F27: m2 emitidos | G27: m2 x precio x uplift x completion | H27: Prueba de instalacion
A28: DPP / Carpeta Madre | B28: ='01_Supuestos'!B8*'01_Supuestos'!B26*(1+'01_Supuestos'!B27)*'01_Supuestos'!B28/1000000 | C28: ='01_Supuestos'!C8*'01_Supuestos'!C26*(1+'01_Supuestos'!C27)*'01_Supuestos'!C28/1000000 | D28: ='01_Supuestos'!D8*'01_Supuestos'!D26*(1+'01_Supuestos'!D27)*'01_Supuestos'!D28/1000000 | E28: ='01_Supuestos'!E8*'01_Supuestos'!E26*(1+'01_Supuestos'!E27)*'01_Supuestos'!E28/1000000 | F28: m2 emitidos | G28: m2 x precio x uplift x completion | H28: Pasaporte/dossier vivo
A29: Network Maintenance | B29: ='01_Supuestos'!B9*'01_Supuestos'!B29*(1+'01_Supuestos'!B30)*'01_Supuestos'!B31/1000000 | C29: ='01_Supuestos'!C9*'01_Supuestos'!C29*(1+'01_Supuestos'!C30)*'01_Supuestos'!C31/1000000 | D29: ='01_Supuestos'!D9*'01_Supuestos'!D29*(1+'01_Supuestos'!D30)*'01_Supuestos'!D31/1000000 | E29: ='01_Supuestos'!E9*'01_Supuestos'!E29*(1+'01_Supuestos'!E30)*'01_Supuestos'!E31/1000000 | F29: Stock vivo | G29: stock x precio x uplift x conversion | H29: Recurrencia sobre base instalada
A30: Data Layers | B30: ='01_Supuestos'!B9*'01_Supuestos'!B32*(1+'01_Supuestos'!B33)*'01_Supuestos'!B34/1000000 | C30: ='01_Supuestos'!C9*'01_Supuestos'!C32*(1+'01_Supuestos'!C33)*'01_Supuestos'!C34/1000000 | D30: ='01_Supuestos'!D9*'01_Supuestos'!D32*(1+'01_Supuestos'!D33)*'01_Supuestos'!D34/1000000 | E30: ='01_Supuestos'!E9*'01_Supuestos'!E32*(1+'01_Supuestos'!E33)*'01_Supuestos'!E34/1000000 | F30: Stock vivo | G30: stock x precio x uplift x adopcion | H30: Datos, reporting, permisos
A31: Total Usage-Based Construction Asset OS | B31: =SUM(B20:B30) | C31: =SUM(C20:C30) | D31: =SUM(D20:D30) | E31: =SUM(E20:E30) | F31: Subtotal | G31: SUM | H31: Subtotal Asset OS
A34: Verticales, marketplace y total ingresos
A35: Concepto | B35: 2026/27 | C35: 2028 | D35: 2029 | E35: 2030 | F35: Driver | G35: Formula | H35: Notas
A36: iPath | B36: ='01_Supuestos'!B38 | C36: ='01_Supuestos'!C38 | D36: ='01_Supuestos'!D38 | E36: ='01_Supuestos'!E38 | F36: Input vertical | G36: Supuestos | H36: Infraestructura urbana industrializada
A37: Moolde | B37: ='01_Supuestos'!B39 | C37: ='01_Supuestos'!C39 | D37: ='01_Supuestos'!D39 | E37: ='01_Supuestos'!E39 | F37: Input vertical | G37: Supuestos | H37: Circularidad/materiales
A38: Internacional | B38: ='01_Supuestos'!B40 | C38: ='01_Supuestos'!C40 | D38: ='01_Supuestos'!D40 | E38: ='01_Supuestos'!E40 | F38: Input vertical | G38: Supuestos | H38: Expansion fuera de mercado inicial
A39: Financial Layer | B39: ='01_Supuestos'!B41 | C39: ='01_Supuestos'!C41 | D39: ='01_Supuestos'!D41 | E39: ='01_Supuestos'!E41 | F39: Input vertical | G39: Supuestos | H39: Datos/servicios financieros
A40: Marketplace | B40: ='01_Supuestos'!B9*'01_Supuestos'!B36*'01_Supuestos'!B35/1000000+'01_Supuestos'!B37 | C40: ='01_Supuestos'!C9*'01_Supuestos'!C36*'01_Supuestos'!C35/1000000+'01_Supuestos'!C37 | D40: ='01_Supuestos'!D9*'01_Supuestos'!D36*'01_Supuestos'!D35/1000000+'01_Supuestos'!D37 | E40: ='01_Supuestos'!E9*'01_Supuestos'!E36*'01_Supuestos'!E35/1000000+'01_Supuestos'!E37 | F40: Stock vivo | G40: stock x fee x penetracion + premium | H40: Canal y servicios sobre red
A42: TOTAL INGRESOS | B42: =B31+SUM(B36:B40) | C42: =C31+SUM(C36:C40) | D42: =D31+SUM(D36:D40) | E42: =E31+SUM(E36:E40) | F42: Total | G42: Asset OS + verticales | H42: Ingresos totales del plan
A43: m2 emitidos | B43: ='01_Supuestos'!B8 | C43: ='01_Supuestos'!C8 | D43: ='01_Supuestos'!D8 | E43: ='01_Supuestos'!E8 | F43: Driver | G43: Supuestos
A44: Stock vivo | B44: ='01_Supuestos'!B9 | C44: ='01_Supuestos'!C9 | D44: ='01_Supuestos'!D9 | E44: ='01_Supuestos'!E9 | F44: Driver | G44: Supuestos

Sheet 03_Detalle_Personal
A1: 03 Detalle de personal
A2: Perfiles, departamentos, sueldo medio y FTE por tramo. Coste en EUR M.
A5: Departamento | B5: Perfil | C5: Sueldo medio EUR/FTE | D5: 2026/27 | E5: 2028 | F5: 2029 | G5: 2030 | H5: Coste 2026/27 | I5: Coste 2028 | J5: Coste 2029 | K5: Coste 2030
A6: Direccion | B6: CEO / Direccion general | C6: 110000 | D6: 1 | E6: 1 | F6: 1 | G6: 1 | H6: =$C6*D6/1000000 | I6: =$C6*E6/1000000 | J6: =$C6*F6/1000000 | K6: =$C6*G6/1000000
A7: Direccion | B7: COO / Direccion operaciones | C7: 105000 | D7: 1 | E7: 1 | F7: 1 | G7: 1 | H7: =$C7*D7/1000000 | I7: =$C7*E7/1000000 | J7: =$C7*F7/1000000 | K7: =$C7*G7/1000000
A8: Direccion | B8: CTO / Direccion producto | C8: 105000 | D8: 1 | E8: 1 | F8: 1 | G8: 1 | H8: =$C8*D8/1000000 | I8: =$C8*E8/1000000 | J8: =$C8*F8/1000000 | K8: =$C8*G8/1000000
A9: Direccion | B9: CFO / Finanzas e inversores | C9: 95000 | D9: 0.5 | E9: 1 | F9: 1 | G9: 1 | H9: =$C9*D9/1000000 | I9: =$C9*E9/1000000 | J9: =$C9*F9/1000000 | K9: =$C9*G9/1000000
A10: Direccion | B10: Direccion comercial / Growth | C10: 90000 | D10: 0.5 | E10: 1 | F10: 1 | G10: 1 | H10: =$C10*D10/1000000 | I10: =$C10*E10/1000000 | J10: =$C10*F10/1000000 | K10: =$C10*G10/1000000
A11: Producto | B11: Product Manager Asset OS | C11: 80000 | D11: 1 | E11: 2 | F11: 3 | G11: 4 | H11: =$C11*D11/1000000 | I11: =$C11*E11/1000000 | J11: =$C11*F11/1000000 | K11: =$C11*G11/1000000
A12: Producto | B12: Product Manager iPath / POI / DPP | C12: 78000 | D12: 1 | E12: 2 | F12: 3 | G12: 4 | H12: =$C12*D12/1000000 | I12: =$C12*E12/1000000 | J12: =$C12*F12/1000000 | K12: =$C12*G12/1000000
A13: Producto | B13: Backend / Platform Engineer | C13: 72000 | D13: 3 | E13: 8 | F13: 14 | G13: 22 | H13: =$C13*D13/1000000 | I13: =$C13*E13/1000000 | J13: =$C13*F13/1000000 | K13: =$C13*G13/1000000
A14: Producto | B14: Frontend / App Engineer | C14: 65000 | D14: 2 | E14: 5 | F14: 8 | G14: 12 | H14: =$C14*D14/1000000 | I14: =$C14*E14/1000000 | J14: =$C14*F14/1000000 | K14: =$C14*G14/1000000
A15: Producto | B15: Mobile / Reading Apps Engineer | C15: 62000 | D15: 1 | E15: 3 | F15: 5 | G15: 8 | H15: =$C15*D15/1000000 | I15: =$C15*E15/1000000 | J15: =$C15*F15/1000000 | K15: =$C15*G15/1000000
A16: Producto | B16: Data / AI Engineer | C16: 80000 | D16: 1 | E16: 4 | F16: 8 | G16: 14 | H16: =$C16*D16/1000000 | I16: =$C16*E16/1000000 | J16: =$C16*F16/1000000 | K16: =$C16*G16/1000000
A17: Producto | B17: GIS Engineer | C17: 65000 | D17: 1 | E17: 2 | F17: 4 | G17: 6 | H17: =$C17*D17/1000000 | I17: =$C17*E17/1000000 | J17: =$C17*F17/1000000 | K17: =$C17*G17/1000000
... A37: G&A | B37: Office / Procurement | C37: 42000 | D37: 0.5 | E37: 1 | F37: 2 | G37: 3 | H37: =$C37*D37/1000000 | I37: =$C37*E37/1000000 | J37: =$C37*F37/1000000 | K37: =$C37*G37/1000000
A38: TOTAL PERSONAL | D38: =SUM(D6:D37) | E38: =SUM(E6:E37) | F38: =SUM(F6:F37) | G38: =SUM(G6:G37) | H38: =SUM(H6:H37) | I38: =SUM(I6:I37) | J38: =SUM(J6:J37) | K38: =SUM(K6:K37)

Sheet 04_OPEX_Operativo
A1: 04 OPEX operativo
A2: Detalle no-personal por concepto y driver. EUR M.
A5: Area | B5: Concepto | C5: 2026/27 | D5: 2028 | E5: 2029 | F5: 2030 | G5: Driver | H5: Notas
A6: Producto y Tecnologia | B6: =0.10+'01_Supuestos'!B9*0.14/1000000+'02_Detalle_Ingresos'!B42*0.002 | C6: =0.10+'01_Supuestos'!C9*0.14/1000000+'02_Detalle_Ingresos'!C42*0.002 | D6: =0.10+'01_Supuestos'!D9*0.14/1000000+'02_Detalle_Ingresos'!D42*0.002 | E6: =0.10+'01_Supuestos'!E9*0.14/1000000+'02_Detalle_Ingresos'!E42*0.002 | G6: Stock vivo + ingresos | H6: Infraestructura core, bases de datos, almacenamiento y procesamiento.
A7: Producto y Tecnologia | B7: =0.04+'03_Detalle_Personal'!D38*1800/1000000 | C7: =0.04+'03_Detalle_Personal'!E38*1800/1000000 | D7: =0.04+'03_Detalle_Personal'!F38*1800/1000000 | E7: =0.04+'03_Detalle_Personal'!G38*1800/1000000 | G7: FTE + base | H7: Seguridad, logs, copias, hardening, monitorizacion y continuidad.
A8: Producto y Tecnologia | B8: =0.05+'03_Detalle_Personal'!D38*6500/1000000 | C8: =0.05+'03_Detalle_Personal'!E38*6500/1000000 | D8: =0.05+'03_Detalle_Personal'!F38*6500/1000000 | E8: =0.05+'03_Detalle_Personal'!G38*6500/1000000 | G8: FTE | H8: Herramientas de desarrollo, diseño, gestion, test y soporte.
A9: Producto y Tecnologia | B9: =0.03+'02_Detalle_Ingresos'!B42*0.004 | C9: =0.03+'02_Detalle_Ingresos'!C42*0.004 | D9: =0.03+'02_Detalle_Ingresos'!D42*0.004 | E9: =0.03+'02_Detalle_Ingresos'!E42*0.004 | G9: Ingresos | H9: Uso de API, generacion de proyectos, validaciones y automatizaciones.
A10: Producto y Tecnologia | B10: 0.08 | C10: 0.16 | D10: 0.25 | E10: 0.35 | G10: Input ramp | H10: Ambientes de preproduccion, hardware de pruebas y bancos de ensayo.
A11: Producto y Tecnologia | B11: =0.05+'01_Supuestos'!B8*0.05/1000000 | C11: =0.05+'01_Supuestos'!C8*0.05/1000000 | D11: =0.05+'01_Supuestos'!D8*0.05/1000000 | E11: =0.05+'01_Supuestos'!E8*0.05/1000000 | G11: m2 emitidos | H11: Pruebas de regresion, integracion, fiabilidad y calidad de releases.
A12: Producto y Tecnologia | B12: =0.04+'01_Supuestos'!B9*0.04/1000000 | C12: =0.04+'01_Supuestos'!C9*0.04/1000000 | D12: =0.04+'01_Supuestos'!D9*0.04/1000000 | E12: =0.04+'01_Supuestos'!E9*0.04/1000000 | G12: Stock vivo | H12: Data pipelines, trazas, control de performance y escalabilidad.
A13: Operaciones / Delivery | B13: =0.06+'01_Supuestos'!B8*0.12/1000000 | C13: =0.06+'01_Supuestos'!C8*0.12/1000000 | D13: =0.06+'01_Supuestos'!D8*0.12/1000000 | E13: =0.06+'01_Supuestos'!E8*0.12/1000000 | G13: m2 emitidos | H13: Lectores, neuronas fijas/portatiles, sensores y kits de validacion.
A14: Operaciones / Delivery | B14: =0.04+'01_Supuestos'!B8*0.08/1000000 | C14: =0.04+'01_Supuestos'!C8*0.08/1000000 | D14: =0.04+'01_Supuestos'!D8*0.08/1000000 | E14: =0.04+'01_Supuestos'!E8*0.08/1000000 | G14: m2 emitidos | H14: Material de implantacion, pruebas de campo y reposicion.
A15: Operaciones / Delivery | B15: =0.08+'02_Detalle_Ingresos'!B42*0.004 | C15: =0.08+'02_Detalle_Ingresos'!C42*0.004 | D15: =0.08+'02_Detalle_Ingresos'!D42*0.004 | E15: =0.08+'02_Detalle_Ingresos'!E42*0.004 | G15: Ingresos | H15: Ensayos, validacion externa, certificaciones y controles de terceros.
A16: Operaciones / Delivery | B16: ='01_Supuestos'!B10*0.028 | C16: ='01_Supuestos'!C10*0.028 | D16: ='01_Supuestos'!D10*0.028 | E16: ='01_Supuestos'!E10*0.028 | G16: Partners activos | H16: Alta de partners, parametrizacion, sesiones tecnicas y soporte inicial.
A17: Operaciones / Delivery | B17: =0.04+'01_Supuestos'!B10*0.012 | C17: =0.04+'01_Supuestos'!C10*0.012 | D17: =0.04+'01_Supuestos'!D10*0.012 | E17: =0.04+'01_Supuestos'!E10*0.012 | G17: Partners activos | H17: Contenidos, manuales, protocolos y entrenamiento de red.
A18: Operaciones / Delivery | B18: ='01_Supuestos'!B10*0.035 | C18: ='01_Supuestos'!C10*0.035 | D18: ='01_Supuestos'!D10*0.035 | E18: ='01_Supuestos'!E10*0.035 | G18: Partners activos | H18: Despliegue, visitas, puesta en marcha y supervision de casos.
A19: Operaciones / Delivery | B19: =0.03+'01_Supuestos'!B8*0.05/1000000 | C19: =0.03+'01_Supuestos'!C8*0.05/1000000 | D19: =0.03+'01_Supuestos'!D8*0.05/1000000 | E19: =0.03+'01_Supuestos'!E8*0.05/1000000 | G19: m2 emitidos | H19: Sustituciones, desplazamientos urgentes y logistica de incidencias.
A20: Operaciones / Delivery | B20: 0.05 | C20: 0.12 | D20: 0.2 | E20: 0.3 | G20: Input ramp | H20: Stock de demostracion, prototipos y material comercial/operativo.
A21: Customer Success / Data | B21: =0.03+'03_Detalle_Personal'!D38*1200/1000000 | C21: =0.03+'03_Detalle_Personal'!E38*1200/1000000 | D21: =0.03+'03_Detalle_Personal'!F38*1200/1000000 | E21: =0.03+'03_Detalle_Personal'!G38*1200/1000000 | G21: FTE | H21: Sistemas de soporte, bases de conocimiento y atencion a clientes.
A22: Customer Success / Data | B22: =0.05+'01_Supuestos'!B9*0.07/1000000 | C22: =0.05+'01_Supuestos'!C9*0.07/1000000 | D22: =0.05+'01_Supuestos'!D9*0.07/1000000 | E22: =0.05+'01_Supuestos'!E9*0.07/1000000 | G22: Stock vivo | H22: Explotacion de datos, reporting recurrente y control de evidencias.
A23: Customer Success / Data | B23: =0.03+'02_Detalle_Ingresos'!B42*0.0015 | C23: =0.03+'02_Detalle_Ingresos'!C42*0.0015 | D23: =0.03+'02_Detalle_Ingresos'!D42*0.0015 | E23: =0.03+'02_Detalle_Ingresos'!E42*0.0015 | G23: Ingresos | H23: Monitorizacion de SLA, calidad y cumplimiento operativo.
A24: Customer Success / Data | B24: =0.02+'01_Supuestos'!B10*0.008 | C24: =0.02+'01_Supuestos'!C10*0.008 | D24: =0.02+'01_Supuestos'!D10*0.008 | E24: =0.02+'01_Supuestos'!E10*0.008 | G24: Partners activos | H24: Biblioteca documental, plantillas de entrega y guias de uso.
A25: GTM / Marketing | B25: 0.2 | C25: 0.45 | D25: 0.7 | E25: 1 | G25: Input ramp | H25: Marca, web, narrativa, piezas comerciales y documentacion publica.
A26: GTM / Marketing | B26: 0.09 | C26: 0.25 | D26: 0.45 | E26: 0.7 | G26: Input ramp | H26: Demostradores, presencia sectorial, jornadas y pruebas comerciales.
A27: GTM / Marketing | B27: ='02_Detalle_Ingresos'!B42*0.02 | C27: ='02_Detalle_Ingresos'!C42*0.02 | D27: ='02_Detalle_Ingresos'!D42*0.02 | E27: ='02_Detalle_Ingresos'!E42*0.02 | G27: Ingresos | H27: Comisiones, referral, canal y soporte a partners comerciales.
A28: GTM / Marketing | B28: =0.04+'01_Supuestos'!B10*0.015 | C28: =0.04+'01_Supuestos'!C10*0.015 | D28: =0.04+'01_Supuestos'!D10*0.015 | E28: =0.04+'01_Supuestos'!E10*0.015 | G28: Partners activos | H28: Materiales, sesiones, campañas con partners y soporte a venta.
A29: GTM / Marketing | B29: 0.05 | C29: 0.1 | D29: 0.14 | E29: 0.18 | G29: Input ramp | H29: Documentos, decks, actualizaciones y material de reporting externo.
A30: GTM / Marketing | B30: =0.03+'03_Detalle_Personal'!D38*1000/1000000 | C30: =0.03+'03_Detalle_Personal'!E38*1000/1000000 | D30: =0.03+'03_Detalle_Personal'!F38*1000/1000000 | E30: =0.03+'03_Detalle_Personal'!G38*1000/1000000 | G30: FTE | H30: CRM, analitica comercial, reporting de pipeline y automatizaciones.
A31: G&A | B31: 0.16 | C31: 0.28 | D31: 0.42 | E31: 0.58 | G31: Input ramp | H31: Legal, propiedad intelectual, contratos, compliance y privacidad.
A32: G&A | B32: =0.14+'02_Detalle_Ingresos'!B42*0.003 | C32: =0.14+'02_Detalle_Ingresos'!C42*0.003 | D32: =0.14+'02_Detalle_Ingresos'!D42*0.003 | E32: =0.14+'02_Detalle_Ingresos'!E42*0.003 | G32: Ingresos | H32: Administracion, seguros, reporting financiero, bancos y control.
A33: G&A | B33: ='03_Detalle_Personal'!D38*5500/1000000 | C33: ='03_Detalle_Personal'!E38*5500/1000000 | D33: ='03_Detalle_Personal'!F38*5500/1000000 | E33: ='03_Detalle_Personal'!G38*5500/1000000 | G33: FTE | H33: Puestos, equipos, hub operativo, comunicaciones y facilities.
A34: G&A | B34: 0.14 | C34: 0.24 | D34: 0.35 | E34: 0.5 | G34: Input ramp | H34: Auditoria, asesores especialistas, reporting y soporte corporativo.
A35: G&A | B35: =0.03+'03_Detalle_Personal'!D38*2500/1000000 | C35: =0.03+'03_Detalle_Personal'!E38*2500/1000000 | D35: =0.03+'03_Detalle_Personal'!F38*2500/1000000 | E35: =0.03+'03_Detalle_Personal'!G38*2500/1000000 | G35: FTE | H35: Seleccion, formacion, onboarding operativo y cultura operativa.
A36: G&A | B36: 0.04 | C36: 0.08 | D36: 0.12 | E36: 0.18 | G36: Input ramp | H36: Gobernanza, secretariado, consejo, reporting accionarial.
A37: Reserva / contingencia | B37: =SUM(B6:B36)*0.04 | C37: =SUM(C6:C36)*0.04 | D37: =SUM(D6:D36)*0.04 | E37: =SUM(E6:E36)*0.04 | G37: % subtotal no-personal | H37: Reserva del 4% sobre OPEX operativo no-personal antes de contingencia.
A38: TOTAL OPEX OPERATIVO | C38: =SUM(C6:C37) | D38: =SUM(D6:D37) | E38: =SUM(E6:E37) | F38: =SUM(F6:F37)

Sheet 05_Detalle_OPEX
A1: 05 Detalle de OPEX
A2: Roll-up de OPEX por categoria. EUR M.
A5: Categoria | B5: 2026/27 | C5: 2028 | D5: 2029 | E5: 2030 | F5: Driver / detalle | G5: Notas | H5: Fuente
A6: Personal | B6: ='03_Detalle_Personal'!H38 | C6: ='03_Detalle_Personal'!I38 | D6: ='03_Detalle_Personal'!J38 | E6: ='03_Detalle_Personal'!K38 | F6: Perfiles x FTE x sueldo | G6: Detalle por perfil | H6: 03_Detalle_Personal
A7: Producto y Tecnologia | B7: =SUMIF('04_OPEX_Operativo'!$A$6:$A$37,"Producto y Tecnologia",'04_OPEX_Operativo'!C$6:C$37) | C7: =SUMIF('04_OPEX_Operativo'!$A$6:$A$37,"Producto y Tecnologia",'04_OPEX_Operativo'!D$6:D$37) | D7: =SUMIF('04_OPEX_Operativo'!$A$6:$A$37,"Producto y Tecnologia",'04_OPEX_Operativo'!E$6:E$37) | E7: =SUMIF('04_OPEX_Operativo'!$A$6:$A$37,"Producto y Tecnologia",'04_OPEX_Operativo'!F$6:F$37) | F7: Cloud + seguridad + IA/API + QA | G7: Detalle no-personal | H7: 04_OPEX_Operativo
A8: Operaciones / Delivery | B8: =SUMIF('04_OPEX_Operativo'!$A$6:$A$37,"Operaciones / Delivery",'04_OPEX_Operativo'!C$6:C$37) | C8: =SUMIF('04_OPEX_Operativo'!$A$6:$A$37,"Operaciones / Delivery",'04_OPEX_Operativo'!D$6:D$37) | D8: =SUMIF('04_OPEX_Operativo'!$A$6:$A$37,"Operaciones / Delivery",'04_OPEX_Operativo'!E$6:E$37) | E8: =SUMIF('04_OPEX_Operativo'!$A$6:$A$37,"Operaciones / Delivery",'04_OPEX_Operativo'!F$6:F$37) | F8: IoT + QA + training + field | G8: Detalle no-personal | H8: 04_OPEX_Operativo
A9: Customer Success / Data | B9: =SUMIF('04_OPEX_Operativo'!$A$6:$A$37,"Customer Success / Data",'04_OPEX_Operativo'!C$6:C$37) | C9: =SUMIF('04_OPEX_Operativo'!$A$6:$A$37,"Customer Success / Data",'04_OPEX_Operativo'!D$6:D$37) | D9: =SUMIF('04_OPEX_Operativo'!$A$6:$A$37,"Customer Success / Data",'04_OPEX_Operativo'!E$6:E$37) | E9: =SUMIF('04_OPEX_Operativo'!$A$6:$A$37,"Customer Success / Data",'04_OPEX_Operativo'!F$6:F$37) | F9: Soporte + datos + SLA | G9: Detalle no-personal | H9: 04_OPEX_Operativo
A10: GTM / Marketing | B10: =SUMIF('04_OPEX_Operativo'!$A$6:$A$37,"GTM / Marketing",'04_OPEX_Operativo'!C$6:C$37) | C10: =SUMIF('04_OPEX_Operativo'!$A$6:$A$37,"GTM / Marketing",'04_OPEX_Operativo'!D$6:D$37) | D10: =SUMIF('04_OPEX_Operativo'!$A$6:$A$37,"GTM / Marketing",'04_OPEX_Operativo'!E$6:E$37) | E10: =SUMIF('04_OPEX_Operativo'!$A$6:$A$37,"GTM / Marketing",'04_OPEX_Operativo'!F$6:F$37) | F10: Marca + canal + eventos + CRM | G10: Detalle no-personal | H10: 04_OPEX_Operativo
A11: G&A | B11: =SUMIF('04_OPEX_Operativo'!$A$6:$A$37,"G&A",'04_OPEX_Operativo'!C$6:C$37) | C11: =SUMIF('04_OPEX_Operativo'!$A$6:$A$37,"G&A",'04_OPEX_Operativo'!D$6:D$37) | D11: =SUMIF('04_OPEX_Operativo'!$A$6:$A$37,"G&A",'04_OPEX_Operativo'!E$6:E$37) | E11: =SUMIF('04_OPEX_Operativo'!$A$6:$A$37,"G&A",'04_OPEX_Operativo'!F$6:F$37) | F11: Legal + finanzas + oficina + governance | G11: Detalle no-personal | H11: 04_OPEX_Operativo
A12: Reserva / contingencia | B12: =SUMIF('04_OPEX_Operativo'!$A$6:$A$37,"Reserva / contingencia",'04_OPEX_Operativo'!C$6:C$37) | C12: =SUMIF('04_OPEX_Operativo'!$A$6:$A$37,"Reserva / contingencia",'04_OPEX_Operativo'!D$6:D$37) | D12: =SUMIF('04_OPEX_Operativo'!$A$6:$A$37,"Reserva / contingencia",'04_OPEX_Operativo'!E$6:E$37) | E12: =SUMIF('04_OPEX_Operativo'!$A$6:$A$37,"Reserva / contingencia",'04_OPEX_Operativo'!F$6:F$37) | F12: 4% subtotal OPEX operativo | G12: Contingencia | H12: 04_OPEX_Operativo
A13: OPEX no-personal | B13: =SUM(B7:B12) | C13: =SUM(C7:C12) | D13: =SUM(D7:D12) | E13: =SUM(E7:E12) | F13: SUM categorias no-personal | G13: Subtotal
A14: TOTAL OPEX | B14: =B6+B13 | C14: =C6+C13 | D14: =D6+D13 | E14: =E6+E13 | F14: Personal + no-personal | G14: Alimenta cuenta de resultados
A15: OPEX / ingresos | B15: =IF('02_Detalle_Ingresos'!B42=0,0,B14/'02_Detalle_Ingresos'!B42) | C15: =IF('02_Detalle_Ingresos'!C42=0,0,C14/'02_Detalle_Ingresos'!C42) | D15: =IF('02_Detalle_Ingresos'!D42=0,0,D14/'02_Detalle_Ingresos'!D42) | E15: =IF('02_Detalle_Ingresos'!E42=0,0,E14/'02_Detalle_Ingresos'!E42) | F15: Total OPEX / ingresos | G15: Ratio operativo

Sheet 06_Cuenta_Resultados
A1: 06 Cuenta de resultados
A2: Ingresos, margen bruto, OPEX, EBITDA, EBIT, resultado antes de impuestos y resultado neto. EUR M.
A5: Concepto | B5: 2026/27 | C5: 2028 | D5: 2029 | E5: 2030 | F5: Notas / driver
A6: Ingresos totales | B6: ='02_Detalle_Ingresos'!B42 | C6: ='02_Detalle_Ingresos'!C42 | D6: ='02_Detalle_Ingresos'!D42 | E6: ='02_Detalle_Ingresos'!E42 | F6: Desde Detalle de ingresos
A7: Contribucion digitalizacion fabricante | B7: ='02_Detalle_Ingresos'!B20*'01_Supuestos'!B51 | C7: ='02_Detalle_Ingresos'!C20*'01_Supuestos'!C51 | D7: ='02_Detalle_Ingresos'!D20*'01_Supuestos'!D51 | E7: ='02_Detalle_Ingresos'!E20*'01_Supuestos'!E51 | F7: Revenue x GM especifico
A8: Contribucion digitalizacion montaje | B8: ='02_Detalle_Ingresos'!B21*'01_Supuestos'!B52 | C8: ='02_Detalle_Ingresos'!C21*'01_Supuestos'!C52 | D8: ='02_Detalle_Ingresos'!D21*'01_Supuestos'!D52 | E8: ='02_Detalle_Ingresos'!E21*'01_Supuestos'!E52 | F8: Revenue x GM especifico
A9: Contribucion fee fabricante | B9: ='02_Detalle_Ingresos'!B22*'01_Supuestos'!B53 | C9: ='02_Detalle_Ingresos'!C22*'01_Supuestos'!C53 | D9: ='02_Detalle_Ingresos'!D22*'01_Supuestos'!D53 | E9: ='02_Detalle_Ingresos'!E22*'01_Supuestos'!E53 | F9: Revenue x GM especifico
A10: Contribucion fee montaje | B10: ='02_Detalle_Ingresos'!B23*'01_Supuestos'!B54 | C10: ='02_Detalle_Ingresos'!C23*'01_Supuestos'!C54 | D10: ='02_Detalle_Ingresos'!D23*'01_Supuestos'!D54 | E10: ='02_Detalle_Ingresos'!E23*'01_Supuestos'!E54 | F10: Revenue x GM especifico
A11: Contribucion resto Asset OS | B11: =('02_Detalle_Ingresos'!B31-SUM('02_Detalle_Ingresos'!B20:B23))*'01_Supuestos'!B46 | C11: =('02_Detalle_Ingresos'!C31-SUM('02_Detalle_Ingresos'!C20:C23))*'01_Supuestos'!C46 | D11: =('02_Detalle_Ingresos'!D31-SUM('02_Detalle_Ingresos'!D20:D23))*'01_Supuestos'!D46 | E11: =('02_Detalle_Ingresos'!E31-SUM('02_Detalle_Ingresos'!E20:E23))*'01_Supuestos'!E46 | F11: Subtotal Asset OS excl. lineas anteriores x margen Asset OS
A12: Contribucion iPath | B12: ='02_Detalle_Ingresos'!B36*'01_Supuestos'!B47 | C12: ='02_Detalle_Ingresos'!C36*'01_Supuestos'!C47 | D12: ='02_Detalle_Ingresos'!D36*'01_Supuestos'!D47 | E12: ='02_Detalle_Ingresos'!E36*'01_Supuestos'!E47 | F12: Revenue x margen iPath
A13: Contribucion Marketplace | B13: ='02_Detalle_Ingresos'!B40*'01_Supuestos'!B48 | C13: ='02_Detalle_Ingresos'!C40*'01_Supuestos'!C48 | D13: ='02_Detalle_Ingresos'!D40*'01_Supuestos'!D48 | E13: ='02_Detalle_Ingresos'!E40*'01_Supuestos'!E48 | F13: Revenue x margen Marketplace
A14: Contribucion Moolde | B14: ='02_Detalle_Ingresos'!B37*'01_Supuestos'!B55 | C14: ='02_Detalle_Ingresos'!C37*'01_Supuestos'!C55 | D14: ='02_Detalle_Ingresos'!D37*'01_Supuestos'!D55 | E14: ='02_Detalle_Ingresos'!E37*'01_Supuestos'!E55 | F14: Revenue x margen Moolde
A15: Contribucion Internacional | B15: ='02_Detalle_Ingresos'!B38*'01_Supuestos'!B49 | C15: ='02_Detalle_Ingresos'!C38*'01_Supuestos'!C49 | D15: ='02_Detalle_Ingresos'!D38*'01_Supuestos'!D49 | E15: ='02_Detalle_Ingresos'!E38*'01_Supuestos'!E49 | F15: Revenue x margen internacional
A16: Contribucion Financial Layer | B16: ='02_Detalle_Ingresos'!B39*'01_Supuestos'!B50 | C16: ='02_Detalle_Ingresos'!C39*'01_Supuestos'!C50 | D16: ='02_Detalle_Ingresos'!D39*'01_Supuestos'!D50 | E16: ='02_Detalle_Ingresos'!E39*'01_Supuestos'!E50 | F16: Revenue x margen Financial Layer
A17: Margen bruto / contribucion total | B17: =SUM(B7:B16) | C17: =SUM(C7:C16) | D17: =SUM(D7:D16) | E17: =SUM(E7:E16) | F17: SUM contribuciones
A18: % margen bruto | B18: =IF(B6=0,0,B17/B6) | C18: =IF(C6=0,0,C17/C6) | D18: =IF(D6=0,0,D17/D6) | E18: =IF(E6=0,0,E17/E6) | F18: Contribucion / ingresos
A19: OPEX personal | B19: =-'05_Detalle_OPEX'!B6 | C19: =-'05_Detalle_OPEX'!C6 | D19: =-'05_Detalle_OPEX'!D6 | E19: =-'05_Detalle_OPEX'!E6 | F19: Gasto operativo de plantilla
A20: OPEX no-personal | B20: =-'05_Detalle_OPEX'!B13 | C20: =-'05_Detalle_OPEX'!C13 | D20: =-'05_Detalle_OPEX'!D13 | E20: =-'05_Detalle_OPEX'!E13 | F20: Gasto operativo no-personal
A21: OPEX total | B21: =SUM(B19:B20) | C21: =SUM(C19:C20) | D21: =SUM(D19:D20) | E21: =SUM(E19:E20) | F21: Personal + no-personal
A22: EBITDA | B22: =B17+B21 | C22: =C17+C21 | D22: =D17+D21 | E22: =E17+E21 | F22: Margen bruto + OPEX total
A23: % margen EBITDA | B23: =IF(B6=0,0,B22/B6) | C23: =IF(C6=0,0,C22/C6) | D23: =IF(D6=0,0,D22/D6) | E23: =IF(E6=0,0,E22/E6) | F23: EBITDA / ingresos
A24: Amortizacion / D&A | B24: =-'01_Supuestos'!B60 | C24: =-'01_Supuestos'!C60 | D24: =-'01_Supuestos'!D60 | E24: =-'01_Supuestos'!E60 | F24: Depreciacion y amortizacion contable
A25: EBIT | B25: =B22+B24 | C25: =C22+C24 | D25: =D22+D24 | E25: =E22+E24 | F25: EBITDA + D&A
A26: Resultado financiero | B26: =-'01_Supuestos'!B61 | C26: =-'01_Supuestos'!C61 | D26: =-'01_Supuestos'!D61 | E26: =-'01_Supuestos'!E61 | F26: Gasto financiero estimado
A27: Resultado antes de impuestos | B27: =B25+B26 | C27: =C25+C26 | D27: =D25+D26 | E27: =E25+E26 | F27: EBIT + resultado financiero
A28: Impuesto sobre sociedades | B28: =-MAX(0,B27*'01_Supuestos'!B58) | C28: =-MAX(0,C27*'01_Supuestos'!C58) | D28: =-MAX(0,D27*'01_Supuestos'!D58) | E28: =-MAX(0,E27*'01_Supuestos'!E58) | F28: Sobre EBT positivo
A29: Resultado neto | B29: =B27+B28 | C29: =C27+C28 | D29: =D27+D28 | E29: =E27+E28 | F29: EBT + impuestos
A30: % margen neto | B30: =IF(B6=0,0,B29/B6) | C30: =IF(C6=0,0,C29/C6) | D30: =IF(D6=0,0,D29/D6) | E30: =IF(E6=0,0,E29/E6) | F30: Resultado neto / ingresos

Sheet 07_Caja_CAPEX_WC
A1: 07 Caja, CAPEX y working capital
A2: FCF antes de financiacion y caja final. EUR M.
A5: Concepto | B5: 2026/27 | C5: 2028 | D5: 2029 | E5: 2030 | F5: Notas / driver
A6: EBITDA | B6: ='06_Cuenta_Resultados'!B22 | C6: ='06_Cuenta_Resultados'!C22 | D6: ='06_Cuenta_Resultados'!D22 | E6: ='06_Cuenta_Resultados'!E22 | F6: Desde cuenta de resultados
A7: Ingresos | B7: ='02_Detalle_Ingresos'!B42 | C7: ='02_Detalle_Ingresos'!C42 | D7: ='02_Detalle_Ingresos'!D42 | E7: ='02_Detalle_Ingresos'!E42 | F7: Desde Detalle de ingresos
A8: Crecimiento ingresos | B8: =B7 | C8: =C7-B7 | D8: =D7-C7 | E8: =E7-D7 | F8: Primer periodo usa ingresos del periodo; siguientes son variacion vs periodo anterior.
A9: Working capital incremental | B9: =-MAX(0,B8)*'01_Supuestos'!B56 | C9: =-MAX(0,C8)*'01_Supuestos'!C56 | D9: =-MAX(0,D8)*'01_Supuestos'!D56 | E9: =-MAX(0,E8)*'01_Supuestos'!E56 | F9: Crecimiento positivo x WC %
A10: Capex | B10: =-'01_Supuestos'!B57 | C10: =-'01_Supuestos'!C57 | D10: =-'01_Supuestos'!D57 | E10: =-'01_Supuestos'!E57 | F10: Desde supuestos
A11: Impuestos pagados | B11: ='06_Cuenta_Resultados'!B28 | C11: ='06_Cuenta_Resultados'!C28 | D11: ='06_Cuenta_Resultados'!D28 | E11: ='06_Cuenta_Resultados'!E28 | F11: Desde cuenta de resultados
A12: FCF antes financiacion | B12: =SUM(B6,B9:B11) | C12: =SUM(C6,C9:C11) | D12: =SUM(D6,D9:D11) | E12: =SUM(E6,E9:E11) | F12: EBITDA - WC - capex - impuestos
A13: Financiacion | B13: ='01_Supuestos'!B59 | C13: ='01_Supuestos'!C59 | D13: ='01_Supuestos'!D59 | E13: ='01_Supuestos'!E59 | F13: Separada de EBITDA/FCF operativo
A14: Flujo neto caja | B14: =B12+B13 | C14: =C12+C13 | D14: =D12+D13 | E14: =E12+E13 | F14: FCF + financiacion
A15: Caja final | B15: =B14 | C15: =B15+C14 | D15: =C15+D14 | E15: =D15+E14 | F15: Caja acumulada

Sheet 08_Control
A1: 08 Control
A2: Controles de coherencia del modelo financiero.
A5: Comprobacion | B5: Actual | C5: Esperado | D5: Diferencia | E5: Estado | F5: Referencia | G5: Notas
A6: m2 total mantiene base | B6: =SUM('01_Supuestos'!B8:E8) | C6: ='01_Supuestos'!B5 | D6: =B6-C6 | E6: =IF(ABS(D6)<1,"OK","FALLO") | F6: 01_Supuestos!B5:B8 | G6: Total emitido debe igualar la curva base original ajustada.
A7: Ingresos total suma componentes | B7: ='02_Detalle_Ingresos'!E42 | C7: =SUM('02_Detalle_Ingresos'!E31,'02_Detalle_Ingresos'!E36:E40) | D7: =B7-C7 | E7: =IF(ABS(D7)<0.01,"OK","FALLO") | F7: 02_Detalle_Ingresos | G7: Total ingresos = Asset OS + verticales.
A8: OPEX total suma categorias | B8: ='05_Detalle_OPEX'!E14 | C8: =SUM('05_Detalle_OPEX'!E6,'05_Detalle_OPEX'!E13) | D8: =B8-C8 | E8: =IF(ABS(D8)<0.01,"OK","FALLO") | F8: 05_Detalle_OPEX | G8: Total OPEX = personal + OPEX no-personal.
A9: Personal suma perfiles | B9: ='03_Detalle_Personal'!K38 | C9: =SUM('03_Detalle_Personal'!K6:K37) | D9: =B9-C9 | E9: =IF(ABS(D9)<0.01,"OK","FALLO") | F9: 03_Detalle_Personal | G9: Coste personal = suma perfil x FTE.
A10: EBITDA calcula margen menos OPEX | B10: ='06_Cuenta_Resultados'!E22 | C10: ='06_Cuenta_Resultados'!E17+'06_Cuenta_Resultados'!E21 | D10: =B10-C10 | E10: =IF(ABS(D10)<0.01,"OK","FALLO") | F10: 06_Cuenta_Resultados | G10: EBITDA = margen bruto + OPEX total negativo.
A11: Resultado neto calcula EBT menos impuestos | B11: ='06_Cuenta_Resultados'!E29 | C11: ='06_Cuenta_Resultados'!E27+'06_Cuenta_Resultados'!E28 | D11: =B11-C11 | E11: =IF(ABS(D11)<0.01,"OK","FALLO") | F11: 06_Cuenta_Resultados | G11: Resultado neto = resultado antes de impuestos + impuestos.
A12: Caja final roll-forward | B12: ='07_Caja_CAPEX_WC'!E15 | C12: =SUM('07_Caja_CAPEX_WC'!B14:E14) | D12: =B12-C12 | E12: =IF(ABS(D12)<0.01,"OK","FALLO") | F12: 07_Caja_CAPEX_WC | G12: Caja final = caja previa + flujo neto.
A13: Sin ingresos negativos materiales | B13: =MIN('02_Detalle_Ingresos'!B20:E42) | C13: =-0.01 | D13: =MIN(0,B13-C13) | E13: =IF(B13>=C13,"OK","REVISAR") | F13: 02_Detalle_Ingresos | G13: Control simplificado de signo.
A14: Inversion 4,2M conciliada | B14: ='12_INV_Familias'!C21 | C14: ='11_INV_Resumen_4_2M'!B6 | D14: =B14-C14 | E14: =IF(ABS(D14)<1,"OK","FALLO") | F14: 11_INV_Resumen_4_2M / 12_INV_Familias | G14: Total familias debe conciliar con valor actual de referencia.
A15: Uso fondos 300K conciliado | B15: ='14_300K_Uso_Fondos'!B12 | C15: ='13_300K_Resumen'!B6 | D15: =B15-C15 | E15: =IF(ABS(D15)<0.01,"OK","FALLO") | F15: 13_300K_Resumen / 14_300K_Uso_Fondos | G15: Uso de fondos debe sumar 300.000 EUR.
A16: ESTADO MODELO | B16: =COUNTIF(E6:E15,"FALLO")+COUNTIF(E6:E15,"REVISAR") | C16: =0 | D16: =B16-C16 | E16: =IF(B16=0,"OK","REVISAR") | F16: Todas las comprobaciones | G16: OK si no hay fallos ni revisiones.

Sheet 09_Documentacion_Soporte
A1: 09 Documentacion soporte
A2: Fuentes y convenciones de lectura del modelo.
A5: Item | B5: Valor | C5: Unidades | D5: Periodo/as-of | E5: Tipo de fuente | F5: Nombre/ref | G5: Responsable | H5: Notas
A6: Documento principal | B6: Business Plan total definitivo | C6: docx | D6: Actual | E6: Documento CUEVA | F6: CUEVA_BP_TOTAL_DEFINITIVO_INVERSORES.docx | G6: CUEVA | H6: Exposicion completa de proyecto, producto, lineas, valoracion, plan 300K y plan 2030.
A7: Plan 300K | B7: Business Plan independiente 2026/2027 | C7: docx | D7: 2026/27 | E7: Documento CUEVA | F7: CUEVA_BP_300K_2026_2027_INDEPENDIENTE.docx | G7: CUEVA | H7: Plan inmediato separado del plan total para evitar mezclar uso de fondos con scale case.
A8: Valoracion 4,2M | B8: 4.216.174,70 EUR | C8: EUR | D8: 2012/13-actualidad | E8: Informe de inversion acumulada | F8: CUEVA_VALORACION_4_2M_INVERSION_PRODUCTO.docx | G8: CUEVA | H8: Valor de referencia por inversion acumulada, profundidad tecnica y producto construido.
A9: Modelo financiero | B9: Modelo definitivo | C9: xlsx | D9: 2026/27-2030 | E9: Modelo CUEVA | F9: CUEVA_MODELO_FINANCIERO_DEFINITIVO.xlsx | G9: CUEVA | H9: Plan 2030, inversion acumulada 4,2M y plan 300K en bloques separados.
A10: Convencion | B10: EUR M salvo indicacion | C10: convencion | D10: todos | E10: Convencion de modelo | F10: 00_Portada | G10: CUEVA | H10: Ingresos, OPEX, cuenta de resultados y caja expresados en millones de euros.
A11: Ingresos | B11: Conceptos y drivers detallados | C11: EUR M | D11: 2026/27-2030 | E11: Modelo financiero | F11: 02_Detalle_Ingresos | G11: CUEVA | H11: Digitalizacion, usage fees, producto, verticales, marketplace y capa financiera.
A12: Personal | B12: Perfil x sueldo x FTE | C12: EUR M | D12: 2026/27-2030 | E12: Modelo financiero | F12: 03_Detalle_Personal | G12: CUEVA | H12: Plan editable de plantilla por departamento y perfil.
A13: OPEX | B13: Detalle operativo y corporativo | C13: EUR M | D13: 2026/27-2030 | E13: Modelo financiero | F13: 04_OPEX_Operativo / 05_Detalle_OPEX | G13: CUEVA | H13: Desglose de costes no-personal, contingencia y estructura operativa.
A14: Control | B14: OK/REVISAR/FALLO | C14: estado | D14: 2026/27-2030 | E14: Control de coherencia | F14: 08_Control | G14: CUEVA | H14: Controles de m2, ingresos, OPEX, personal, EBITDA, resultado neto, caja e inversion.
A15: Paquetes de producto | B15: P0-P5 + verticales | C15: producto | D15: todos | E15: Modelo financiero | F15: 10_Paquetes_Producto | G15: CUEVA | H15: Conexion entre producto, entregables, drivers economicos y gates.
A16: Inversion acumulada | B16: 4.216.174,70 EUR | C16: EUR | D16: hasta actualidad | E16: Informe inversion/producto | F16: 11_INV_Resumen_4_2M / 12_INV_Familias | G16: CUEVA | H16: Bloque separado del forecast para no mezclar valor construido con cuenta de resultados futura.
... A18: Puente 300K escala | B18: Plan minimo vs scale case | C18: lectura | D18: 2027 | E18: Modelo financiero | F18: 16_300K_Puente_Escala | G18: CUEVA | H18: Separa plan obligatorio de crecimiento financiado.

Sheet 10_Paquetes_Producto
A1: 10 Paquetes de producto
A2: Conexion entre producto, entregables, drivers economicos y plan 2030. Se conservan los nombres propios de paquetes/producto.
A5: Paquete / producto | B5: TRL actual | C5: Rol economico | D5: Driver principal | E5: Tareas clave | F5: Entregable / gate | G5: Hoja economica | H5: Notas
A6: P0 Discovery & Blueprint | B6: 8/9 | C6: Entrada consultiva y configuracion de caso | D6: Partners / proyecto | E6: Diagnostico, parametrizacion, alcance tecnico, plan de datos, mapa de evidencias | F6: Blueprint validado y caso listo para red | G6: 02_Detalle_Ingresos | H6: Reduce riesgo de implantacion y acelera activacion.
A7: P1 Factory Core | B7: 8/9 | C7: Digitalizacion fabricante y fee de red | D7: m2 fabricados verificados | E7: Alta fabricante, geometria base, reglas de produccion, trazabilidad de fabrica, conexion con stock | F7: Fabricante operativo en red | G7: 02_Detalle_Ingresos | H7: Base del ingreso por fabricante y del trigger de m2.
A8: P2 Warehouse & Logistics | B8: 8/9 | C8: Trazabilidad de stock, preparacion y movimientos | D8: Stock vivo / partners | E8: Lecturas, lotes, ubicaciones, expediciones, integracion con evidencias y reporting | F8: Stock trazable y auditable | G8: 02_Detalle_Ingresos | H8: Conecta fabricacion, logistica y datos operativos.
A9: P3 Site Proof / POI | B9: 8/9 | C9: Evidence pack de instalacion | D9: m2 instalados/verificados | E9: Lectura en obra, validacion de montaje, incidencias, cierre POI, fotografia/evidencia | F9: POI cerrado por activo | G9: 02_Detalle_Ingresos | H9: Paquete clave para defender evidencia de obra y servicio al cliente.
A10: P4 DPP / Carpeta Madre | B10: 8/9 | C10: Pasaporte documental y dossier vivo | D10: m2 con DPP completado | E10: Documentacion tecnica, evidencias, responsables, permisos, trazabilidad documental | F10: DPP / Carpeta Madre emitida | G10: 02_Detalle_Ingresos | H10: Capa documental que convierte el activo en verificable y mantenible.
A11: P5 Data / Risk / Market | B11: 8/9 | C11: Datos, reporting, riesgo y marketplace | D11: Stock vivo / penetracion | E11: Data layers, indicadores, reporting, scoring operativo, permisos, APIs, marketplace | F11: Datos explotables y servicios recurrentes | G11: 02_Detalle_Ingresos | H11: Motor de recurrencia y expansion de margen.
A12: CUEVA Designer | B12: 8/9 | C12: Diseño/generativo/API | D12: m2 emitidos x adopcion | E12: Configurador, generacion de proyectos, reglas, outputs y conexion a API | F12: Proyecto generado/validado | G12: 02_Detalle_Ingresos | H12: Integra el desarrollo de vivienda generativa en la plataforma.
A13: CUEVA Manager | B13: 8/9 | C13: Gestion operacional de proyectos y agentes | D13: m2 emitidos x adopcion | E13: Project room, permisos, tareas, control de cambios, colaboracion y estado | F13: Proyecto gestionado en plataforma | G13: 02_Detalle_Ingresos | H13: Interfaz de gestion para agentes de la red.
A14: iPath | B14: 8/9 | C14: Vertical de infraestructura urbana industrializada | D14: Revenue vertical | E14: Diseño de rutas, piezas, instalacion, datos, mantenimiento y reporting | F14: Caso iPath operativo | G14: 02_Detalle_Ingresos | H14: Linea de producto con ingresos propios.
A15: Moolde | B15: 8/9 | C15: Circularidad/materiales | D15: Revenue vertical | E15: Registro de materiales, stock, trazabilidad, recuperacion y valorizacion | F15: Caso Moolde operativo | G15: 02_Detalle_Ingresos | H15: Complementa circularidad, residuos y eficiencia material.
A16: Activos digitales | B16: 6/7 | C16: Capa financiera, tokenizacion y modelos NFT | D16: Financial Layer | E16: Modelo financiero, identidad digital, derechos, gobernanza y evidencias asociadas | F16: Capa financiera preparada para siguiente fase | G16: 02_Detalle_Ingresos | H16: Se mantiene en TRL inferior frente al core operativo.
A17: Red de partners | B17: 8/9 | C17: Escala comercial y operativa | D17: Partners activos | E17: Onboarding, formacion, soporte, protocolos, QA, enablement y seguimiento | F17: Partner activo y medible | G17: 03_Detalle_Personal / 04_OPEX_Operativo | H17: Afecta ingresos, OPEX, capacidad de entrega y velocidad de escala.

Sheet 11_INV_Resumen_4_2M
A1: 11 INV Resumen 4,2M
A2: Bloque separado de inversion acumulada y valor actual de referencia. No forma parte del motor operativo 2030.
A5: Indicador | B5: Valor | C5: Unidad | D5: Lectura | E5: Fuente / soporte | F5: Notas
A6: Valor actual de referencia | B6: 4216174.7 | C6: EUR | D6: Inversion historica acumulada, IP, producto, casos y relaciones | E6: Informe de inversion y producto / BP inversores | F6: Base de conversacion de valor actual, no DCF.
A7: Total detalle familias | B7: ='12_INV_Familias'!C21 | C7: EUR | D7: Suma de la pestaña 12_INV_Familias | E7: 12_INV_Familias | F7: Debe conciliar con la cifra defendida.
A8: Diferencia conciliacion | B8: =B6-B7 | C8: EUR | D8: Valor de referencia menos detalle | E8: Control de conciliacion | F8: Debe ser cero salvo redondeos.
A9: Criterio de valor | B9: Coste de construccion de activo | C9: texto | D9: Cost-to-build + producto + know-how + documentacion tecnica | E9: Documentacion EDRO/CUEVA | F9: No se presenta como tasacion independiente.
A10: Separacion del modelo | B10: Bloque independiente | C10: texto | D10: Estas hojas no alimentan ingresos/OPEX/P&L 2030 | E10: Estructura separada | F10: Evita mezclar inversion acumulada con forecast.
A13: Presupuestos externos y referencias tecnicas
A14: Referencia | B14: Importe | C14: Unidad | D14: Lectura | E14: Relacion con inversion 4,2M | F14: Uso correcto | G14: Fuente | H14: Notas
A15: CDTI | B15: 990000 | C15: EUR | D15: Valida sistema fisico, DfMA, prototipos, ensayos y maquinaria | E15: Soporte tecnico externo superior a una parte del coste construido | F15: Referencia tecnica, sin importe a devolver | G15: Presupuesto/memoria CDTI | H15: CDTI no implica importe a devolver.
A16: Cervera | B16: 840000 | C16: EUR | D16: Valida sistema digital 4.0, datos, software, IoT y fabricacion inteligente | E16: Soporte tecnico de software/datos y capa industrial | F16: Referencia tecnica | G16: Presupuesto Cervera | H16: Conecta con CEREBRO, DPP, POI, GIS y neuronas.
A17: Tax Lease Leyton | B17: 2020000 | C17: EUR | D17: Valida placas modulares inteligentes y desarrollo asociado | E17: Referencia de alcance presupuestado frente a inversion defendida | F17: Referencia tecnica/fiscal documentada | G17: Tax Lease Leyton | H17: No se imputan ingresos no documentados.
A18: Tax Lease Arcano / CEREBRO | B18: 5724400 | C18: EUR | D18: Sistema ciberfisico completo | E18: Presupuesto externo por encima de la inversion defendida | F18: Referencia de alcance | G18: Tax Lease Arcano | H18: Fabricacion, almacen, transporte, montaje, vida y comunidad.
A19: CEREBRO por fases | B19: 6408402 | C19: EUR | D19: Matriz completa de paquetes tecnicos | E19: Mapa de alcance superado por productizacion actual | F19: Referencia de paquetes | G19: CEREBRO por fases | H19: Sirve para conectar inversion a paquetes de producto.
A20: Valor de referencia CUEVA | B20: 4216174.7 | C20: EUR | D20: Activo ya construido y consistente | E20: Cifra base de la compañia hasta la fecha | F20: Base de negociacion | G20: Informe inversion/producto | H20: Incluye inversion acumulada y productizacion.

Sheet 12_INV_Familias
A1: 12 INV Familias tecnicas
A2: Desglose de los 4.216.174,70 EUR por familias tecnicas y lectura de producto.
A5: Familia | B5: Periodo | C5: Inversion EUR | D5: % total | E5: TRL actual | F5: Producto / paquete asociado | G5: Lectura de producto | H5: Fuente / nota
A6: Fundacion tecnica | B6: 2012/13-2018 | C6: 425000 | D6: =C6/$C$21 | E6: 8/9 | F6: Arquitectura fisica, mecanica, geometria base | G6: CUEVA OS no nace como software aislado: nace sobre una arquitectura fisica y una logica constructiva propia. | H6: Asignacion de etapa inicial.
A7: Sistema fisico + DfMA | B7: 2019-2022/23 | C7: 273326 | D7: =C7/$C$21 | E7: 8/9 | F7: Factory Core / identidad pieza-activo | G7: Base de la identidad pieza-activo; sin ella no hay POI/DPP verificable. | H7: CDTI / desarrollo industrial.
A8: CEREBRO + software/datos | B8: 2019-2022/23 | C8: 375000 | D8: =C8/$C$21 | E8: 8/9 | F8: Designer, Project Room, DPP, POI | G8: Columna vertebral: Designer, Project Room, DPP, POI y verticales dependen de este nucleo. | H8: Tax Lease / CEREBRO.
A9: IoT + comunicaciones | B9: 2019-2022/23 | C9: 180000 | D9: =C9/$C$21 | E9: 8/9 | F9: Neuronas, lectura, evidencias | G9: Bisagra entre pieza fisica, fabrica, obra y evidencia digital. | H9: Cervera / CEREBRO.
A10: Operativa industrial | B10: 2019-2022/23 | C10: 794759 | D10: =C10/$C$21 | E10: 8/9 | F10: Factory Core, Factory Flow, Site Proof | G10: Base de la Carta de Servicios y de la operacion verificable. | H10: Base EDRO con operativa.
A11: Ingeniero virtual | B11: 2021-2023 | C11: 261965 | D11: =C11/$C$21 | E11: 8/9 | F11: Designer / vivienda generativa / API | G11: Copiloto tecnico: CAD/BIM/calculo, heuristica, predictivos y automatizacion. | H11: CEREBRO / software.
A12: Vida + comunidad | B12: 2021-2023 | C12: 236125 | D12: =C12/$C$21 | E12: 8/9 | F12: Market OS, postventa, circularidad | G12: Postventa, circularidad y economia de plataforma. | H12: CEREBRO por fases.
A13: DPP / pasaporte digital | B13: 2023-act. | C13: 220000 | D13: =C13/$C$21 | E13: 8/9 | F13: DPP / Carpeta Madre | G13: El producto fisico pasa a tener memoria, estado y trazabilidad explotable. | H13: Productizacion CUEVA OS.
A14: POI / prueba de instalacion | B14: 2023-act. | C14: 190000 | D14: =C14/$C$21 | E14: 8/9 | F14: POI Evidence Pack / Site Proof | G14: Obra y montaje convertidos en dato contractual verificable. | H14: Productizacion CUEVA OS.
A15: Activos digitales / tokenizacion | B15: 2023-act. | C15: 260000 | D15: =C15/$C$21 | E15: 6/7 | F15: Financial Layer / activos digitales | G15: Extension hacia financiacion, propiedad digital y economia de plataforma. | H15: White paper blockchain/NFT.
A16: Designer + vivienda generativa | B16: 2023-act. | C16: 255000 | D16: =C16/$C$21 | E16: 8/9 | F16: CUEVA Designer | G16: Generacion automatizada de alternativas de proyecto via API. | H16: Documento vivienda generativa.
A17: GIS + capa territorial | B17: 2023-act. | C17: 150000 | D17: =C17/$C$21 | E17: 8/9 | F17: GIS / red de activos | G17: De proyecto aislado a red de activos geolocalizados. | H17: Productizacion CUEVA OS.
... A20: Market OS + activos comerciales | B20: 2023-act. | C20: 214999.7 | D20: =C20/$C$21 | E20: 8/9 | F20: Market OS / web / marca / materiales comerciales | G20: Convierte la inversion tecnica en lenguaje de mercado. | H20: Marketing, marca y documentacion inversor.
A21: TOTAL INVERSION 4,2M | C21: =SUM(C6:C20) | D21: =SUM(D6:D20)

Sheet 13_300K_Resumen
A1: 13 300K Resumen
A2: Plan 26/27 de 300K separado del plan 2030. Sirve para reducir riesgo, no para mezclarlo con el scale case.
A5: Indicador | B5: Valor | C5: Unidad | D5: Lectura | E5: Hoja soporte | F5: Gate / criterio
A6: Capital plan 26/27 | B6: 300000 | C6: EUR | D6: Financia producto, equipo, Hub Valeriano y salida comercial | E6: 14_300K_Uso_Fondos | F6: Desembolso por gates.
A7: Uso de fondos detallado | B7: ='14_300K_Uso_Fondos'!B12 | C7: EUR | D7: Suma de bloques del plan | E7: 14_300K_Uso_Fondos | F7: Debe sumar 300K.
A8: Revenue 2027 management | B8: 1670000 | C8: EUR | D8: Pipeline base 2027 ajustado | E8: 15_300K_Pipeline_2027 | F8: Reconocer solo con contrato/cobro/m2 verificado.
A9: Revenue 2027 ponderado | B9: 1104000 | C9: EUR | D9: Lectura risk-adjusted | E9: 15_300K_Pipeline_2027 | F9: Probabilidad por proyecto.
A10: EBITDA 2027 management | B10: 313999 | C10: EUR | D10: Contribucion por linea menos OPEX del plan 300K | E10: Modelo financiero base | F10: Controlar contratacion y caja.
A11: EBITDA 2027 ponderado | B11: 11039 | C11: EUR | D11: Lectura prudente del EBITDA | E11: Modelo financiero base | F11: Proteger con gates.
A12: Caja final management | B12: 327599 | C12: EUR | D12: Caja al cierre de 2027 | E12: Modelo financiero base | F12: Cobros por hitos.
A13: Caja final ponderada | B13: 24639 | C13: EUR | D13: Lectura prudente de caja | E13: Modelo financiero base | F13: No activar coste sin evidencia.
A14: m2 plan minimo | B14: 52000 | C14: m2 | D14: m2 ejecutados elegibles del plan 300K | E14: 16_300K_Puente_Escala | F14: Base de fee fabricante + montaje.
A15: Regla de separacion | B15: Independiente del scale case | C15: texto | D15: El 300K activa reduccion de riesgo y prueba comercial; el plan 2030 es otra capa condicionada. | E15: Estructura separada | F15: No mezclar con OPEX/ingresos 2030.
A18: Lectura ejecutiva del 300K
A19: Que activa | B19: Continuidad, producto vendible, Hub Valeriano, primeras pruebas de red, carpeta documental y control de caja.
A20: Que demuestra | B20: Contratos, cobros, m2 verificados, casos POI/DPP, partner piloto y margen por linea.
A21: Alcance | B21: No cubre el scale case 2030 completo ni la estructura de crecimiento acelerado.
A22: Criterio de avance | B22: Liberar coste solo por gates: contrato, anticipo, alcance, m2 verificado, POI/DPP aceptado y soporte operativo.

Sheet 14_300K_Uso_Fondos
A1: 14 300K Uso de fondos
A2: Uso de los 300.000 EUR y gates de liberacion. Bloque separado del plan 2030.
A5: Bloque | B5: Importe | C5: % total | D5: Objetivo | E5: Gate | F5: Tipo | G5: Notas
A6: Equipo base julio-diciembre 2026 | B6: 114600 | C6: =B6/$B$12 | D6: Continuidad directiva, producto, operaciones y comercial | E6: Calendario mensual y roles definidos | F6: Equipo | G6: Asegura continuidad y ejecucion.
A7: Seguridad Social / cumplimiento laboral | B7: 18000 | C7: =B7/$B$12 | D7: Provisiones laborales y regularizacion | E7: Contrataciones formalizadas | F7: Cumplimiento | G7: Evita arrastre operativo.
A8: Software / IT / telecom / IA | B8: 78000 | C8: =B8/$B$12 | D8: CUEVA OS, DPP/POI, cloud, seguridad, demos y campo | E8: Adquisicion por hitos y necesidad de proyecto | F8: Producto | G8: No sobredimensionar sin entregable.
A9: Marketing y comunicacion | B9: 18000 | C9: =B9/$B$12 | D9: Web, deck, casos, CRM y lanzamiento | E9: Producto demo estable | F9: GTM | G9: Soporte comercial e inversor.
A10: Hub Valeriano | B10: 66400 | C10: =B10/$B$12 | D10: Hub Valeriano, showroom y nodo operativo Menorca | E10: Acuerdo Valeriano y layout definido | F10: Hub | G10: Demostrador operativo y activacion territorial.
A11: Legal, auditoria, documentacion y contingencia | B11: 5000 | C11: =B11/$B$12 | D11: Blindaje documental y data room | E11: Checklist audit-ready | F11: Legal / contingencia | G11: Preparar siguientes conversaciones.
A12: TOTAL | B12: =SUM(B6:B11) | C12: =SUM(C6:C11)

Sheet 15_300K_Pipeline_2027
A1: 15 300K Pipeline 2027
A2: Pipeline 2027 del plan 300K: management case, ponderacion de riesgo y evidencia para reconocer ingresos.
A5: Proyecto | B5: Tipo | C5: Base 2027 | D5: Probabilidad | E5: Ponderado | F5: GM | G5: Contribucion base | H5: Contribucion ponderada | I5: Inicio | J5: Fin | K5: Responsable | L5: Contraparte | M5: Gate | N5: Riesgo | O5: Decision si falla
A6: Llar de Mar 2 | B6: Proyecto constructivo | C6: 535000 | D6: 0.8 | E6: =C6*D6 | F6: 0.25 | G6: =C6*F6 | H6: =E6*F6 | I6: Ene-27 | J6: Abr-27 | K6: Luis/Angel | L6: TASH/Barionika | M6: Contrato + anticipo | N6: Margen obra / anticipo | O6: No activar coste sin anticipo
A7: Digitalizacion fabricante partner piloto | B7: Factory Enablement | C7: 250000 | D7: 0.7 | E7: =C7*D7 | F7: 0.58 | G7: =C7*F7 | H7: =E7*F7 | I7: Ene-27 | J7: Abr-27 | K7: Luis/Hernan | L7: Partner industrial | M7: m2 planta validados | N7: m2 reales de planta y alcance firmado | O7: Reclasificar tier o fasear
